<mujoco>
    <option timestep="0.001" integrator="RK4">
		<flag gravity="enable" contact="disable"/>
	</option>
    <worldbody>
        <light diffuse=".5 .5 .5" pos="0 0 3" dir="0 0 -1"/>
        <geom type="plane" pos="0 0 -5" size="3 3 0.1" rgba=".9 0 0 1"/>
        <body name="body0" pos="0 0 -0.5" euler="10 0 0">
            <joint name="joint0" type="ball" pos="0 0 0.5"/>
            <geom name="box0" type="box" size="0.1 0.1 0.5" rgba="0 .9 0 1" mass="1"/>
            <body name="body1" pos="0 0 -1" euler="0 0 0">
                <joint name="joint1" type="ball" pos="0 0 0.5"/>
                <geom name="box1" type="box" size="0.1 0.1 0.5" rgba="0 0 1 1" mass="1"/>
                <body name="body2" pos="0.5 0 -0.5" euler="0 -90 0">
                    <joint name="joint2" type="ball" pos="0 0 0.5"/>
                    <geom name="box2" type="box" size="0.1 0.1 0.5" rgba="0 1 0 1" mass="1"/>
                    <body name="body3" pos="0 0 -1" euler="0 0 0">
                        <joint name="joint3" type="ball" pos="0 0 0.5"/>
                        <geom name="box3" type="box" size="0.1 0.1 0.5" rgba="0 0 1 1" mass="1"/>
                        <body name="body4" pos="0.5 0 -0.5" euler="0 -90 0">
                            <joint name="joint4" type="ball" pos="0 0 0.5"/>
                            <geom name="box4" type="box" size="0.1 0.1 0.5" rgba="0 1 0 1" mass="1"/>
                            <body name="body5" pos="0.5 0 -0.5" euler="0 -90 0">
                                <joint name="joint5" type="ball" pos="0 0 0.5"/>
                                <geom name="box5" type="box" size="0.1 0.1 0.5" rgba="0 0 1 1" mass="1"/>
                                <body name="body6" pos="0 0 -1" euler="0 0 0">
                                    <joint name="joint6" type="ball" pos="0 0 0.5"/>
                                    <geom name="box6" type="box" size="0.1 0.1 0.5" rgba="1 0 0 1" mass="1"/>
                                </body>
                            </body>
                        </body>
                    </body>
                </body>
            </body>
        </body>
    </worldbody>
    <equality>
        <connect  body1="body0" body2="body6" anchor="0 0 -0.5"/>
    </equality>
</mujoco>