<mujoco>
    <option timestep="0.01" integrator="RK4">
		<flag gravity="disable" energy="enable"/>
	</option>
    <compiler autolimits="true"/>
    <worldbody>
        <light diffuse=".5 .5 .5" pos="0 0 3" dir="0 0 -1"/>
        <geom type="plane" pos="0 0 -4" size="3 3 0.1" rgba=".9 0 0 1"/>
        <body name="root" pos="0 0 0" euler="0 0 0">
            <joint name="joint0" type="ball" pos="0 0 1"/>
            <inertial pos="0 0 0" euler="0 0 0" mass="1" diaginertia="0.66667 0.66667 0.66667"/>
            <geom type="capsule" size="0.5 0.5" rgba="0 .9 0 1"/>
            <geom name="box0" type="box" size="0.25 0.5 0.5" rgba="0.9 0 0 1"/>
            <body name="body1" pos="0 0 -2" euler="0 0 0">
                <!-- <joint name="joint1" type="ball" pos="0 0 1"/> -->
                <joint name="joint1" type="ball" pos="0 0 1" range="0 90" solreflimit="0 -190"/>
                <inertial pos="0 0 0" euler="0 0 0" mass="1" diaginertia="0.66667 0.66667 0.66667"/>
                <geom type="capsule" size="0.5 0.5" rgba="0 .9 0 1"/>
                <geom name="box1" type="box" size="0.25 0.5 0.5" rgba="0.9 0 0 1"/>
            </body>
        </body>
    </worldbody>
    <sensor>
        <subtreeangmom  body="root"/>
        <subtreecom   body="root"/>
        <subtreelinvel   body="root"/>
    </sensor>
</mujoco>