<mujoco>
    <option timestep="0.001" integrator="Euler">
		<flag gravity="disable" energy="enable"/>
	</option>
    
    <visual>
        <global offheight="1024" offwidth="1024" azimuth="90" elevation="-30"/>
    </visual>
    <statistic extent="5" center="0 0 0"/>
    
    <!-- <asset> -->
        <!-- <texture type="skybox" builtin="flat" rgb1="0.8 0.8 0.8" rgb2="0.8 0.8 0.8" width="512" height="512"/> -->
    <!-- </asset> -->
    
    <compiler autolimits="true"/>
    <worldbody>
        <light diffuse=".5 .5 .5" pos="0 0 3" dir="0 0 -1"/>
        <geom type="plane" pos="0 0 -10" size="3 3 0.1" rgba=".9 0 0 1"/>
        <body name="root" pos="0 0 -1" euler="0 0 0">
            <joint name="joint_y" type="hinge" pos="0 0 1" axis="0 -1 0"/>
            <joint name="joint_x" type="hinge" pos="0 0 1" axis="-1 0 0"/>
            <joint name="joint_z_twist" type="hinge" pos="0 0 1" range="-45 45" axis="0 0 -1" solreflimit="-10 -150"/>
            <!-- <joint name="joint_z_twist" type="hinge" pos="0 0 1" axis="0 0 -1"/> -->
            <inertial pos="0 0 0" euler="0 0 0" mass="1" diaginertia="0.66667 0.66667 0.66667"/>
            <geom type="box" size="0.5 0.5 1" rgba="0 .9 0 1" mass="1"/>
        </body>
    </worldbody>
</mujoco>