<mujoco>
    <option timestep="0.01" integrator="RK4">
		<flag gravity="disable" energy="enable"/>
	</option>
    <compiler autolimits="true"/>
    <worldbody>
        <light diffuse=".5 .5 .5" pos="0 0 3" dir="0 0 -1"/>
        <geom type="plane" pos="0 0 -8" size="3 3 0.1" rgba=".9 0 0 1"/>
        <body name="root" pos="0 0 0" euler="0 0 0">
            <joint name="joint_y" type="hinge" pos="0 0 1" axis="0 -1 0"/>
            <joint name="joint_x" type="hinge" pos="0 0 1" axis="1 0 0"/>
            <joint name="joint_z_twist" type="hinge" pos="0 0 1" range="0 90" axis="0 0 -1"/>
            <geom type="box" size="0.5 0.5 1" rgba="0 .9 0 1" mass="1"/>
        </body>
    </worldbody>
</mujoco>