<mujoco>
    <option timestep="0.01" integrator="RK4">
		<flag gravity="enable" energy="enable"/>
	</option>
    <compiler autolimits="true"/>
    <worldbody>
        <light diffuse=".5 .5 .5" pos="0 0 3" dir="0 0 -1"/>
        <geom type="plane" pos="0 0 -5" size="3 3 0.1" rgba=".9 0 0 1"/>
        <body name="body0" pos="0 0 0" euler="0 0 0">
            <joint name="joint0" type="ball" pos="0 0 1"/>
            <geom name="left0" type="box" size="0.1 0.1 1" pos="-0.4 0 0" rgba="0 .9 0 1" mass="1"/>
            <geom name="right0" type="box" size="0.1 0.1 1"  pos="0.4 0 0" rgba="0 .9 0 1" mass="1"/>
            <geom name="top0" type="box" size="0.1 0.1 0.5"  pos="0 0 1" euler="0 -90 0" rgba="0 .9 0 1" mass="1"/>
            <geom name="bottom0" type="box" size="0.1 0.1 0.5"  pos="0 0 -1" euler="0 -90 0" rgba="0 .9 0 1" mass="1"/>
        </body>
        <body name="body1" pos="1.1 0 -0.5" euler="90 90 0">
            <joint type="free"/>
            <geom name="left1" type="box" size="0.1 0.1 1" pos="-0.4 0 0" rgba="0 .9 0 1" mass="1"/>
            <geom name="right1" type="box" size="0.1 0.1 1"  pos="0.4 0 0" rgba="0 .9 0 1" mass="1"/>
            <geom name="top1" type="box" size="0.1 0.1 0.5"  pos="0 0 1" euler="0 -90 0" rgba="0 .9 0 1" mass="1"/>
            <geom name="bottom1" type="box" size="0.1 0.1 0.5"  pos="0 0 -1" euler="0 -90 0" rgba="0 .9 0 1" mass="1"/>
        </body>
    </worldbody>
</mujoco>