<mujoco>
    <option timestep="0.001" integrator="Euler">
		<flag gravity="disable" energy="enable"/>
	</option>
    <visual>
         <global offheight="1024" offwidth="1024" azimuth="90" elevation="-30"/>
    </visual>
    <statistic extent="5" center="0 0 0"/>
    
    <compiler autolimits="true"/>
    <worldbody>
        <light diffuse=".5 .5 .5" pos="0 0 3" dir="0 0 -1"/>
        <geom type="plane" pos="0 0 -10" size="3 3 0.1" rgba=".9 0 0 1"/>
        <body name="my_body" pos="0 0 -1" euler="0 0 0">
            <joint name="joint_y" type="hinge" pos="0 0 1" axis="0 -1 0"/>
            <joint name="joint_x" type="hinge" pos="0 0 1" axis="-1 0 0"/>
            <joint name="joint_z_twist" type="hinge" pos="0 0 1" range="-0.000001 0.000001" axis="0 0 -1" solreflimit="-10 -150"/>
            <inertial pos="0 0 0" euler="0 0 0" mass="1" diaginertia="0.66667 0.66667 0.66667"/>
            <geom type="capsule" size="0.5 0.5" rgba="0 .9 0 1" mass="1" solref="-10 -150" solimp="0 0 0" friction="0 0 0" condim="1" priority="0"/>
            <geom type="cylinder" pos="0 -0.25 -1" euler="90 0 0" size="0.1 0.25" rgba="0 0.455 1 1" mass="1"/>   
        </body>
        <body name="ceiling" pos="0 0 1" euler="0 0 0">
            <geom type="box" size="3 3 0.5" rgba="1 0 0 0" solref="-10 -150" solimp="0 0 0" friction="0 0 0" condim="1" priority="1"/>
        </body>
    </worldbody>
</mujoco>   