<mujoco>
    <option timestep="0.01" integrator="Euler">
		<flag gravity="enable" energy="enable"/>
	</option>
    <compiler autolimits="true"/>
    <worldbody>
        <light diffuse=".5 .5 .5" pos="0 0 3" dir="0 0 -1"/>
        <geom type="plane" pos="0 0 -15" size="3 3 0.1" rgba=".9 0 0 1"/>
        <body name="root" pos="0 0 0" euler="0 -90 0">
            <joint name="joint0" type="ball" pos="0 0 1" damping="0.0"/>
            <inertial pos="0 0 0" euler="0 0 0" mass="1" diaginertia="0.66667 0.66667 0.66667"/>
            <geom type="capsule" size="0.5 0.5" rgba="0 .9 0 1"/>
            <geom type="box" size="0.25 0.5 0.5" rgba="0.9 0 0 1"/>
            <body name="body1" pos="0 0 -2" euler="0 0 0">
                <joint name="joint1" type="ball" pos="0 0 1" damping="0.0"/>
                <inertial pos="0 0 0" euler="0 0 0" mass="1" diaginertia="0.66667 0.66667 0.66667"/>
                <geom type="capsule" size="0.5 0.5" rgba="0 .9 0 1"/>
                <geom type="box" size="0.25 0.5 0.5" rgba="0.9 0 0 1"/>
                <body name="body2" pos="0 0 -2" euler="0 0 0">
                    <joint name="joint2" type="ball" pos="0 0 1" damping="0.0"/>
                    <inertial pos="0 0 0" euler="0 0 0" mass="1" diaginertia="0.66667 0.66667 0.66667"/>
                    <geom type="capsule" size="0.5 0.5" rgba="0 .9 0 1"/>
                    <geom type="box" size="0.25 0.5 0.5" rgba="0.9 0 0 1"/>
                    <body name="body3" pos="0 0 -2" euler="0 0 0">
                        <joint name="joint3" type="ball" pos="0 0 1" damping="0.0"/>
                        <inertial pos="0 0 0" euler="0 0 0" mass="1" diaginertia="0.66667 0.66667 0.66667"/>
                        <geom type="capsule" size="0.5 0.5" rgba="0 .9 0 1"/>
                        <geom type="box" size="0.25 0.5 0.5" rgba="0.9 0 0 1"/>
                        <body name="body4" pos="0 0 -2" euler="0 0 0">
                            <joint name="joint4" type="ball" pos="0 0 1" damping="0.0"/>
                            <inertial pos="0 0 0" euler="0 0 0" mass="1" diaginertia="0.66667 0.66667 0.66667"/>
                            <geom type="capsule" size="0.5 0.5" rgba="0 .9 0 1"/>
                            <geom type="box" size="0.25 0.5 0.5" rgba="0.9 0 0 1"/>
                        </body>
                    </body>
                </body>
            </body>
        </body>
    </worldbody>
    <keyframe>
        <key time="0" qpos="1 0 0 0 0.9659258 0.258819 0 0 1 0 0 0 1 0 0 0 1 0 0 0"/>
    </keyframe>
</mujoco>