<mujoco>
    <!-- min distance from root to endfactor is 1.766, max is 2 -->
    <option timestep="0.001">
		<flag gravity="disable"/>
	</option>

   <worldbody>
      <light diffuse=".5 .5 .5" pos="0 0 3" dir="0 0 -1"/>
      <geom type="plane" size="1 1 0.1" rgba=".9 0 0 1"/>

      <body pos="0 0 1.5" euler="0 0 0">
         <joint name="joint0" type="hinge" axis="0 -1 0" pos="0 0 1" damping="0"/>
         <geom name="link0" type="cylinder" pos="0 0 0.5" size="0.05 .5" rgba="1 0 0 1" mass="1"/>
         <body pos="0 0 -1" euler="0 0 0">
            <joint name="joint1" type="hinge" axis="0 -1 0" pos="0 0 1" damping="0"/>
            <geom name="link1" pos="0 0 0.5" type="cylinder" size="0.05 .5" rgba="1 1 1 1" mass="1"/>
         </body>
      </body>
   </worldbody>
   <keyframe>
        <key time="0" qpos="1 0"/>
    </keyframe>
</mujoco> 